Workbook

Sheet INÍCIO
A1: SPIRIT WALKER · ZOO CHOBER CHABER (rota Mattjestic) — Nível 1 → 100
A2: PoE 2 0.5.5 · Liga Forbidden Rites · atualizado 15/09/2026 · rota barata com trade + opção completa. Edite só as células AMARELAS.
A4: ONDE ESTOU AGORA
A5: Seu nível atual | B5: 35
A6: Modo de investimento | B6: Barato
A7: Spirit total (do jogo) | B7: 191
A9: Fase atual | B9: =INDEX(Listas!$B$2:$B$9,MATCH($B$5,Listas!$A$2:$A$9,1))
A10: Etapa | B10: =INDEX(Listas!$E$2:$E$9,MATCH($B$5,Listas!$A$2:$A$9,1))
A11: Quem carrega o dano | B11: =INDEX(Listas!$C$2:$C$9,MATCH($B$5,Listas!$A$2:$A$9,1))
A12: Objetivo da fase | B12: =INDEX(Listas!$D$2:$D$9,MATCH($B$5,Listas!$A$2:$A$9,1))
A13: Último marco (até seu nível) | B13: =IFERROR("Nv "&INDEX('Nível 1-100'!$K$4:$K$103,$B$5)&" — "&INDEX('Nível 1-100'!$J$4:$J$103,$B$5),"")
A14: Próximo marco | B14: =IFERROR("Nv "&INDEX('Nível 1-100'!$A$4:$A$103,MATCH(1,'Nível 1-100'!$I$4:$I$103,0))&" — "&INDEX('Nível 1-100'!$C$4:$C$103,MATCH(1,'Nível 1-100'!$I$4:$I$103,0)),"Você chegou ao fim!")
A15: Compra recomendada agora | B15: =IF($B$6="Barato",INDEX('Nível 1-100'!$E$4:$E$103,$B$5),INDEX('Nível 1-100'!$F$4:$F$103,$B$5))
A16: Progresso de marcos | B16: =IFERROR(COUNTIF('Nível 1-100'!$G$4:$G$103,"Feito")/100,0)
A17: Quests permanentes feitas | B17: =COUNTIF(Quests!$F$4:$F$32,"Feito")&" de "&COUNTA(Quests!$C$4:$C$32)
A19: ROTA S-TIER — FASES (a linha dourada é a sua fase)
A20: Fase | B20: Níveis | C20: Etapa | D20: Carry | E20: Dano player/zoo | F20: Ascendência | G20: Sai da fase quando…
A21: Ato 1 | B21: 1–15 | C21: Twister (leveling) | D21: Você: Twister + Whirling Slash | E21: 100% / 0% | F21: — | G21: King in the Mists (+30 Spirit) · Candlemass (+20 vida) · Botas com MS · Nível ~16
A22: Ato 2 | B22: 16–30 | C22: 1ª Ascendência | D22: Você: Twister + urso | E22: 85% / 15% | F22: Wild Protector (Trial of the Sekhemas, Ato 2) | G22: 1ª Ascendência: Wild Protector · Medallion (+1 Charm Slot) · Currency guardada para a troca
A23: Ato 3 | B23: 31–45 | C23: A troca: macaco + urso | D23: Mighty Silverfist (+ urso + 1 esqueleto) | E23: 5% / 95% | F23: The Natural Order (Trial of Chaos, Ato 3) | G23: Silverfist capturado · Twister fora da barra · Pain Offering + Skeletal Warrior funcionando · Ignagduk (+30 Spirit)
A24: Ato 4 | B24: 46–55 | C24: 2 companions + chaos | D24: Silverfist (+ aura bots) | E24: 0% / 100% | F24: — | G24: 2 companions (macaco + aura) · Evergrasping Ring ×2 + Withering Presence · Testes de resistência do Ato 4 feitos
A25: Interlúdios | B25: 56–64 | C25: Esqueletos para o Muster | D25: Silverfist + zoo | E25: 0% / 100% | F25: — | G25: 2+ tipos de esqueleto (quantos couberem no Spirit) · Muster no macaco · Lythara (+40 Spirit) · Resists no cap
A26: Início do Atlas | B26: 65–77 | C26: Catha's Balance + mapping | D26: Macaco (Silverfist/Zekoa) + zoo | E26: 0% / 100% | F26: The Catha's Balance (Trial nível 60+) | G26: Catha's Balance · Chober Chaber equipada · T1–T10 sem mortes · Juntar ~1 div para o Effigy
A27: T15+ (Effigy) | B27: 78–89 | C27: Chober + Giant's Blood + Effigy | D27: Zekoa + Azmerian Wolf + zoo | E27: 0% / 100% | F27: Idolatry (Trial nível 75+) | G27: Giant's Blood + Chober + Effigy · Zekoa com Extra Crits/Haste · 3 aura bots (com Sylvan's Effigy) · Forgotten Warden + Spirit Vessel
A28: Arbiter / Min-max | B28: 90–100 | C28: Mind Over Matter + 27 companions | D28: Zoo inteiro | E28: 0% / 100% | F28: — | G28: Arbiter · Uber Arbiter
A30: CORREÇÕES FEITAS NA PLANILHA ANTIGA
A31: ✔ Spirit Planner antigo somava a coluna errada (fórmulas deslocadas) — refeito com cálculo de eficiência.
A32: ✔ Darkness Enthroned estava como capacete — é um CINTO (Fine Belt).
A33: ✔ Trenchtimbre é maça de uma mão, não spear.
A34: ✔ Comparação de arma: com Catha's Balance vale dano por golpe, não pDPS.
A35: ✔ Linhas de nível repetiam o mesmo texto; agora cada nível tem o marco real e a tabela vai até o 100.
A36: ✔ Sylvan's Effigy é Stoic Sceptre (drop em área 78+).
A37: ✔ Guia base mandava tirar Trusted Kinship com o Effigy: o meta (99%) mantém.
A38: ✔ Effigy tratado como luxo: custa ~1 div na Forbidden Rites.
A39: ✔ Uniques do meta adicionados: Forgotten Warden, Chober Chaber, The Vertex, Treefingers, Alpha's Howl etc.
A40: ✔ Rota refeita em cima do guia do Mattjestic com foco na Chober Chaber.
A41: ✔ Ball Lightning/Lightning Warp removidos (nenhuma variante do Mattjestic usa).
A42: ✔ Corrigido: Pain Offering é central; Skeletal Cleric serve de alvo; Withering Presence vale com Evergrasping Ring.

Sheet Listas
A1: Nível inicial | B1: Fase | C1: Carry | D1: Objetivo | E1: Tag | F1: Ascendência | H1: Status | I1: Sim/Não | J1: Modo | K1: Tipo | L1: Unidade
A2: 1 | B2: Ato 1 | C2: Você: Twister + Whirling Slash | D2: Subir rápido com Twister. Nada de minion ainda: o foco é chegar ao Ato 3 com dinheiro e nível para trocar para o macaco + Chober Chaber. | E2: Twister (leveling) | F2: — | H2: Pendente | I2: Sim | J2: Barato | K2: Companion | L2: %
A3: 16 | B3: Ato 2 | C3: Você: Twister + urso | D3: Wild Protector na 1ª Ascendência e juntar gold/currency para a troca do Ato 3 (Chober Chaber, The Vertex, Treefingers, Rattling Sceptre). | E3: 1ª Ascendência | F3: Wild Protector (Trial of the Sekhemas, Ato 2) | H3: Fazendo | I3: Não | J3: Completo | K3: Outro | L3: Flat
A4: 31 | B4: Ato 3 | C4: Mighty Silverfist (+ urso + 1 esqueleto) | D4: Capturar o Mighty Silverfist com The Natural Order e trocar a build inteira para minions no mesmo dia: Twister sai, entram macaco, urso, 1 Skeletal Warrior e Pain Offering. | E4: A troca: macaco + urso | F4: The Natural Order (Trial of Chaos, Ato 3) | H4: Feito
A5: 46 | B5: Ato 4 | C5: Silverfist (+ aura bots) | D5: Macaco + 1 beast de aura (o limite do Trusted Kinship é 2 companions), marks e curse. Entram Evergrasping Ring (aliados ganham dano de chaos) e Withering Presence (inimigos recebem mais chaos): as duas peças se multiplicam. | E5: 2 companions + chaos | F5: —
A6: 56 | B6: Interlúdios | C6: Silverfist + zoo | D6: Depois do Lythara (+40 Spirit), somar TIPOS de esqueleto para o Muster, um por vez e só enquanto couber no Spirit: cada tipo diferente = +7% more dano no macaco, e o 2º esqueleto libera o Danse Macabre. Vulnerability tira Armour. | E6: Esqueletos para o Muster | F6: —
A7: 65 | B7: Início do Atlas | C7: Macaco (Silverfist/Zekoa) + zoo | D7: The Catha's Balance transforma o dano da SUA arma em dano dos companions (60% por golpe). É aqui que a Chober Chaber vira o centro: maça de 2 mãos com dano base altíssimo, +Minion Skills e +50 Spirit. | E7: Catha's Balance + mapping | F7: The Catha's Balance (Trial nível 60+)
A8: 78 | B8: T15+ (Effigy) | C8: Zekoa + Azmerian Wolf + zoo | D8: Giant's Blood na árvore (maça de 2 mãos + sceptre), Sylvan's Effigy (companions ilimitados + Azmerian Wolf), Forgotten Warden (Spirit Vessel grátis). Os esqueletos saem, porque o Rattling Sceptre dá lugar ao Effigy. O Skeletal Cleric vira o alvo do Pain Offering. | E8: Chober + Giant's Blood + Effigy | F8: Idolatry (Trial nível 75+)
A9: 90 | B9: Arbiter / Min-max | C9: Zoo inteiro | D9: Endgame do Mattjestic: Mind Over Matter (dano sai da mana primeiro), Mageblood e até 27 companions. O macaco vira o único DPS 'puro'; os outros são aura bots super defensivos. | E9: Mind Over Matter + 27 companions | F9: —

Sheet Nível 1-100
A1: NÍVEL 1 → 100 — marco por nível
A2: Linhas com marco real em negrito. Marque Status = Feito. A linha do seu nível fica dourada (nível no INÍCIO).
A3: Nível | B3: Fase | C3: Faça agora (marco) | D3: Foco da fase | E3: Barato (trade) | F3: Completo (currency) | G3: Status | H3: Carry | I3: aux
A4: 1 | B4: Ato 1 | C4: Twister + Whirling Slash. Spear rare ou Splinter of Lorrata. | D4: Subir rápido com Twister. Nada de minion ainda: o foco é chegar ao Ato 3 com dinheiro e nível para trocar para o macaco + Chober Chaber. | E4: Rare spear com mais dano que cair | F4: Kit de uniques baratos do Mattjestic: Splinter of Lorrata → Skysliver (spear), Foxshade (body), 2× Blackheart (anéis), Goldrim (capacete), Wanderlust (botas), Meginord's Girdle, Surefooted Sigil | G4: Pendente | H4: Você: Twister + Whirling Slash | I4: =IF(AND(C4<>"—",A4>INÍCIO!$B$5),1,0) | J4: =C4 | K4: =A4
A5: 2 | B5: Ato 1 | C5: — | D5: Movement Speed → Vida, Resistências, Dano da spear | E5: Botas com Movement Speed | F5: Todos custam poucos Exalts no trade e fazem o Ato 1–2 voar | G5: Pendente | H5: Você: Twister + Whirling Slash | I5: =IF(AND(C5<>"—",A5>INÍCIO!$B$5),1,0) | J5: =IF(C5<>"—",C5,J4) | K5: =IF(C5<>"—",A5,K4)
A6: 3 | B6: Ato 1 | C6: — | D6: Movement Speed → Vida, Resistências, Dano da spear | E6: Qualquer escudo/buckler com Evasion | F6: Kit de uniques baratos do Mattjestic: Splinter of Lorrata → Skysliver (spear), Foxshade (body), 2× Blackheart (anéis), Goldrim (capacete), Wanderlust (botas), Meginord's Girdle, Surefooted Sigil | G6: Pendente | H6: Você: Twister + Whirling Slash | I6: =IF(AND(C6<>"—",A6>INÍCIO!$B$5),1,0) | J6: =IF(C6<>"—",C6,J5) | K6: =IF(C6<>"—",A6,K5)
A7: 4 | B7: Ato 1 | C7: Twister liberado. Herald of Ice quando tiver Spirit. | D7: Movement Speed → Vida, Resistências, Dano da spear | E7: Rare spear com mais dano que cair | F7: Todos custam poucos Exalts no trade e fazem o Ato 1–2 voar | G7: Pendente | H7: Você: Twister + Whirling Slash | I7: =IF(AND(C7<>"—",A7>INÍCIO!$B$5),1,0) | J7: =IF(C7<>"—",C7,J6) | K7: =IF(C7<>"—",A7,K6)
A8: 5 | B8: Ato 1 | C8: — | D8: Movement Speed → Vida, Resistências, Dano da spear | E8: Botas com Movement Speed | F8: Kit de uniques baratos do Mattjestic: Splinter of Lorrata → Skysliver (spear), Foxshade (body), 2× Blackheart (anéis), Goldrim (capacete), Wanderlust (botas), Meginord's Girdle, Surefooted Sigil | G8: Pendente | H8: Você: Twister + Whirling Slash | I8: =IF(AND(C8<>"—",A8>INÍCIO!$B$5),1,0) | J8: =IF(C8<>"—",C8,J7) | K8: =IF(C8<>"—",A8,K7)
A9: 6 | B9: Ato 1 | C9: — | D9: Movement Speed → Vida, Resistências, Dano da spear | E9: Qualquer escudo/buckler com Evasion | F9: Todos custam poucos Exalts no trade e fazem o Ato 1–2 voar | G9: Pendente | H9: Você: Twister + Whirling Slash | I9: =IF(AND(C9<>"—",A9>INÍCIO!$B$5),1,0) | J9: =IF(C9<>"—",C9,J8) | K9: =IF(C9<>"—",A9,K8)
A10: 7 | B10: Ato 1 | C10: — | D10: Movement Speed → Vida, Resistências, Dano da spear | E10: Rare spear com mais dano que cair | F10: Kit de uniques baratos do Mattjestic: Splinter of Lorrata → Skysliver (spear), Foxshade (body), 2× Blackheart (anéis), Goldrim (capacete), Wanderlust (botas), Meginord's Girdle, Surefooted Sigil | G10: Pendente | H10: Você: Twister + Whirling Slash | I10: =IF(AND(C10<>"—",A10>INÍCIO!$B$5),1,0) | J10: =IF(C10<>"—",C10,J9) | K10: =IF(C10<>"—",A10,K9)
A11: 8 | B11: Ato 1 | C11: Hunting Grounds: The Crowbell (2 weapon set points). | D11: Movement Speed → Vida, Resistências, Dano da spear | E11: Botas com Movement Speed | F11: Todos custam poucos Exalts no trade e fazem o Ato 1–2 voar | G11: Pendente | H11: Você: Twister + Whirling Slash | I11: =IF(AND(C11<>"—",A11>INÍCIO!$B$5),1,0) | J11: =IF(C11<>"—",C11,J10) | K11: =IF(C11<>"—",A11,K10)
A12: 9 | B12: Ato 1 | C12: — | D12: Movement Speed → Vida, Resistências, Dano da spear | E12: Qualquer escudo/buckler com Evasion | F12: Kit de uniques baratos do Mattjestic: Splinter of Lorrata → Skysliver (spear), Foxshade (body), 2× Blackheart (anéis), Goldrim (capacete), Wanderlust (botas), Meginord's Girdle, Surefooted Sigil | G12: Pendente | H12: Você: Twister + Whirling Slash | I12: =IF(AND(C12<>"—",A12>INÍCIO!$B$5),1,0) | J12: =IF(C12<>"—",C12,J11) | K12: =IF(C12<>"—",A12,K11)
A13: 10 | B13: Ato 1 | C13: Freythorn: King in the Mists (+30 Spirit). | D13: Movement Speed → Vida, Resistências, Dano da spear | E13: Rare spear com mais dano que cair | F13: Todos custam poucos Exalts no trade e fazem o Ato 1–2 voar | G13: Pendente | H13: Você: Twister + Whirling Slash | I13: =IF(AND(C13<>"—",A13>INÍCIO!$B$5),1,0) | J13: =IF(C13<>"—",C13,J12) | K13: =IF(C13<>"—",A13,K12)
A14: 11 | B14: Ato 1 | C14: — | D14: Movement Speed → Vida, Resistências, Dano da spear | E14: Botas com Movement Speed | F14: Kit de uniques baratos do Mattjestic: Splinter of Lorrata → Skysliver (spear), Foxshade (body), 2× Blackheart (anéis), Goldrim (capacete), Wanderlust (botas), Meginord's Girdle, Surefooted Sigil | G14: Pendente | H14: Você: Twister + Whirling Slash | I14: =IF(AND(C14<>"—",A14>INÍCIO!$B$5),1,0) | J14: =IF(C14<>"—",C14,J13) | K14: =IF(C14<>"—",A14,K13)
A15: 12 | B15: Ato 1 | C15: — | D15: Movement Speed → Vida, Resistências, Dano da spear | E15: Qualquer escudo/buckler com Evasion | F15: Todos custam poucos Exalts no trade e fazem o Ato 1–2 voar | G15: Pendente | H15: Você: Twister + Whirling Slash | I15: =IF(AND(C15<>"—",A15>INÍCIO!$B$5),1,0) | J15: =IF(C15<>"—",C15,J14) | K15: =IF(C15<>"—",A15,K14)
A16: 13 | B16: Ato 1 | C16: — | D16: Movement Speed → Vida, Resistências, Dano da spear | E16: Rare spear com mais dano que cair | F16: Kit de uniques baratos do Mattjestic: Splinter of Lorrata → Skysliver (spear), Foxshade (body), 2× Blackheart (anéis), Goldrim (capacete), Wanderlust (botas), Meginord's Girdle, Surefooted Sigil | G16: Pendente | H16: Você: Twister + Whirling Slash | I16: =IF(AND(C16<>"—",A16>INÍCIO!$B$5),1,0) | J16: =IF(C16<>"—",C16,J15) | K16: =IF(C16<>"—",A16,K15)
... A103: 100 | B103: Arbiter / Min-max | C103: Uber Arbiter. | D103: Mana (Mind Over Matter) → +Minion Skills, Spirit, Evasion/Deflection | E103: Setup do T15 + Mind Over Matter (Lavianga's Spirits sustenta) | F103: Runeforged Pariah Mask · Drakeskin Boots · Barbed Bracers (rares/runeforged do Mattjestic) | G103: Pendente | H103: Zoo inteiro | I103: =IF(AND(C103<>"—",A103>INÍCIO!$B$5),1,0) | J103: =IF(C103<>"—",C103,J102) | K103: =IF(C103<>"—",A103,K102)

Sheet Rota por Fase
A1: ROTA POR FASE — o que jogar, comprar e evitar
A2: Cada bloco é uma fase. 'Barato' = começar com pouco no trade; 'Completo' = seguir a build como deve ser.
A4: ATO 1 · Nv 1–15 · Twister (leveling)
A5: Objetivo | B5: Subir rápido com Twister. Nada de minion ainda: o foco é chegar ao Ato 3 com dinheiro e nível para trocar para o macaco + Chober Chaber.
A6: Carry | B6: Você: Twister + Whirling Slash
A7: Ascendência | B7: —
A8: Árvore | B8: Nós de Twister/projétil perto do início da Huntress. É a única fase em que dano de ataque do jogador faz sentido.
A9: Rotação | B9: Whirling Slash até formar o redemoinho → Twister atravessando o redemoinho (fica maior e mais forte) → Parry para bloquear e contra-atacar bosses → Spear Throw para puxar de longe
A10: Evite | B10: Gastar pontos em minion agora · Comprar gear caro para o Twister: ele sai da barra no Ato 3
A11: Sai da fase quando | B11: King in the Mists (+30 Spirit) · Candlemass (+20 vida) · Botas com MS · Nível ~16
A12: Barato (trade) | D12: Completo (currency)
A13: • Rare spear com mais dano que cair | D13: • Kit de uniques baratos do Mattjestic: Splinter of Lorrata → Skysliver (spear), Foxshade (body), 2× Blackheart (anéis), Goldrim (capacete), Wanderlust (botas), Meginord's Girdle, Surefooted Sigil
A14: • Botas com Movement Speed | D14: • Todos custam poucos Exalts no trade e fazem o Ato 1–2 voar
A15: • Qualquer escudo/buckler com Evasion
A16: Prioridade de stats: Movement Speed > Vida > Resistências > Dano da spear
A18: ATO 2 · Nv 16–30 · 1ª Ascendência
A19: Objetivo | B19: Wild Protector na 1ª Ascendência e juntar gold/currency para a troca do Ato 3 (Chober Chaber, The Vertex, Treefingers, Rattling Sceptre).
A20: Carry | B20: Você: Twister + urso
A21: Ascendência | B21: Wild Protector (Trial of the Sekhemas, Ato 2)
A22: Árvore | B22: Ainda Twister, mas já caminhe para o lado de companion da árvore para o respec do Ato 3 ficar barato.
A23: Rotação | B23: Mesma rotação de Twister → O urso segura o aggro dos bosses
A24: Evite | B24: Gastar todo o gold: o respec do Ato 3 é caro
A25: Sai da fase quando | B25: 1ª Ascendência: Wild Protector · Medallion (+1 Charm Slot) · Currency guardada para a troca
A26: Barato (trade) | D26: Completo (currency)
A27: • Rare spear + botas com MS | D27: • Skysliver (spear) · Foxshade · 2× Blackheart · Goldrim · Wanderlust · Surefooted Sigil · Meginord's Girdle
A28: • Meginord's Girdle se faltar Strength | D28: • Comece a guardar para: Chober Chaber (~2 ex), Treefingers (~5 ex), Rattling Sceptre (qualquer), The Vertex versão 'Equipment' (~0,4 div)
A29: Prioridade de stats: Movement Speed > Vida > Resistências > Spirit
A31: ATO 3 · Nv 31–45 · A troca: macaco + urso
A32: Objetivo | B32: Capturar o Mighty Silverfist com The Natural Order e trocar a build inteira para minions no mesmo dia: Twister sai, entram macaco, urso, 1 Skeletal Warrior e Pain Offering.
A33: Carry | B33: Mighty Silverfist (+ urso + 1 esqueleto)
A34: Ascendência | B34: The Natural Order (Trial of Chaos, Ato 3)
A35: Árvore | B35: Árvore do Mattjestic (Ato 3): Trusted Kinship, Bond of the Mamba, Bond of the Cat, Unspoken Bond, e defesa de Evasion (Blur, Catlike Agility, Escape Velocity). Zero nós de ataque.
A36: Rotação | B36: Entre no pack e deixe o macaco e o urso baterem → Unearth no chão: cria Bone Constructs e quebra Armour (Armour Break III) → Pain Offering em cima do boss (espeta um Skeletal Warrior): +velocidade e +dano para todos os minions por 6 s → Raise Shield se o boss for dar um golpe grande
A37: Evite | B37: Matar o Silverfist antes de ter The Natural Order · Manter Twister/Whirling depois da troca · Ball Lightning / Lightning Warp: não fazem nada pelo macaco
A38: Sai da fase quando | B38: Silverfist capturado · Twister fora da barra · Pain Offering + Skeletal Warrior funcionando · Ignagduk (+30 Spirit)
A39: Barato (trade) | D39: Completo (currency)
A40: • Rattling Sceptre (main) + Trenchtimbre (offhand) — exatamente como o Mattjestic | D40: • Chober Chaber + Rattling Sceptre (com Treefingers dando Giant's Blood)
A41: • Midnight Braid (cinto) · Foxshade/Wanderlust/Blackheart mantidos | D41: • The Vertex versão 'Equipment has no Attribute Requirements' para zerar os requisitos triplicados
A42: • Meginord's Girdle se faltar Strength | D42: • Enfolding Dawn (+100 Spirit no body) para caber mais minions
A43: Prioridade de stats: +Minion Skills > Spirit > Movement Speed > Vida > Resistências
...

Sheet Skills & Supports
A1: SKILLS & SUPPORTS — rota Chober Chaber (Mattjestic)
A2: Filtre a coluna Fase. Coluna J explica cada skill; no fim da aba, o que cada support faz.
A3: Fase | B3: Skill | C3: Set | D3: Support 1 | E3: Support 2 | F3: Support 3 | G3: Support 4 | H3: Support 5 | I3: Função | J3: Por que está na build
A4: Ato 1 | B4: Twister | C4: — | D4: Retreat III | E4: Elemental Armament III | F4: Projectile Acceleration I | I4: Dano principal | J4: Twister é a skill de leveling mais rápida da Huntress: redemoinhos que atravessam packs inteiros.
A5: Ato 1 | B5: Whirling Slash | C5: — | D5: Rapid Attacks I | E5: Rage II | I5: Cria o redemoinho | J5: Cada Whirling Slash cria/aumenta um redemoinho; o Twister disparado por dentro dele ganha dano e tamanho.
A6: Ato 1 | B6: Herald of Ice | C6: — | D6: Cold Attunement | E6: Concentrated Area | I6: Clear extra | J6: Inimigos congelados explodem e limpam o resto do pack sem apertar nada.
A7: Ato 1 | B7: Parry | C7: — | I7: Defesa ativa | J7: Bloqueia o próximo golpe e deixa o inimigo vulnerável: salva de bosses do Ato 1–2.
A8: Ato 1 | B8: Spear Throw | C8: — | I8: Puxar de longe | J8: Vem da própria spear; útil para puxar packs.
A9: Ato 2 | B9: Wild Protector | C9: Asc. | D9: Magnified Area I | E9: Rage II | I9: Tank + dano extra | J9: O urso não conta no limite de companions: é um minion grátis que segura bosses e dá Intimidate.
A10: Ato 2 | B10: Twister | C10: — | D10: Retreat III | E10: Elemental Armament III | F10: Projectile Acceleration I | I10: Dano principal | J10: Continua sendo o dano até capturar o macaco.
A11: Ato 2 | B11: Whirling Slash | C11: — | D11: Rapid Attacks I | E11: Bleed I | I11: Redemoinho | J11: Bleed no Whirling ajuda nos bosses.
A12: Ato 2 | B12: Parry | C12: — | I12: Defesa ativa | J12: Continua útil até o Ato 3.
A13: Ato 2 | B13: Spear Throw | C13: — | I13: Puxar de longe | J13: Vem da spear.
A14: Ato 3 | B14: Tame Beast (Mighty Silverfist) | C14: — | D14: Feeding Frenzy II | E14: Rage II | F14: Rapid Attacks I | G14: Heft | I14: CARRY | J14: O macaco é o dano da build inteira: bate físico em área, muito rápido, com 25% de chance de crítico base. Tudo abaixo existe para deixá-lo mais forte ou mais vivo.
A15: Ato 3 | B15: Wild Protector | C15: Asc. | D15: Magnified Area I | I15: Tank | J15: Segura o aggro e conta como mais um TIPO de minion para o Muster.
A16: Ato 3 | B16: Skeletal Warrior (1 esqueleto) | C16: — | D16: Sacrificial Lamb I | E16: Meat Shield I | I16: Combustível do Pain Offering | J16: Vem como gem do Rattling Sceptre. Você só precisa de UM esqueleto vivo: ele é o alvo que o Pain Offering espeta. Não é para dar dano. Sacrificial Lamb garante que o espinho pegue ele (e nunca o macaco) e Meat Shield mantém ele vivo.
A17: Ato 3 | B17: Pain Offering | C17: — | D17: Prolonged Duration II | E17: Sacrificial Offering | I17: Buff de dano dos minions | J17: Espeta 1 esqueleto: minions a até 6 m ganham até +29% attack speed e +58% dano. Não reserva Spirit, só gasta mana. Danse Macabre só entra quando você tiver 2 esqueletos vivos (Interlúdios em diante); com 1 esqueleto ele não funciona.
A18: Ato 3 | B18: Unearth | C18: — | D18: Armour Break III | I18: Quebra de Armour + corpos | J18: Spell sua que cria Bone Constructs dos corpos e, com Armour Break III, tira Armour do inimigo: o macaco passa a bater o dano físico inteiro.
A19: Ato 3 | B19: Raise Shield | C19: — | I19: Defesa ativa | J19: Só funciona com escudo ou buckler equipado. Com sceptre + maça (o set desta rota) ele não pode ser usado: deixe fora da barra se não tiver escudo.
A20: Ato 3 | B20: Tame Beast (2º beast: aura) | C20: — | D20: Last Gasp | E20: Loyalty | I20: Aura bot | J20: Entra quando o Spirit deixar (depois do Ignagduk, +30 Spirit, no nível ~40). Escolha pelo modificador de aura (Haste/Physical), não pelo dano. Last Gasp mantém a aura viva, Loyalty faz ele tomar parte do seu dano.
A21: Ato 3 | B21: Tame Beast (vazia) | C21: — | I21: Captura | J21: Deixe uma gem de Tame Beast livre para capturar o próximo beast com mod bom.
A22: Ato 3 | B22: Twister | C22: — | D22: Retreat III | E22: Elemental Armament III | I22: Só até capturar | J22: Tire da barra no respec.
A23: Ato 3 | B23: Whirling Slash | C23: — | D23: Rapid Attacks I | E23: Bleed I | I23: Só até capturar | J23: Tire da barra no respec.
A24: Ato 4 | B24: Tame Beast (Mighty Silverfist) | C24: — | D24: Feeding Frenzy II | E24: Rage II | F24: Rapid Attacks II | G24: Heft | I24: CARRY | J24: Rapid Attacks sobe para II: mais golpes por segundo.
A25: Ato 4 | B25: Wild Protector | C25: Asc. | D25: Magnified Area I | E25: Armour Break III | I25: Tank + Armour Break | J25: O urso também passa a quebrar Armour, somando com o Unearth.
A26: Ato 4 | B26: Skeletal Warrior (ou 1 Arsonist) | C26: — | D26: Sacrificial Lamb I | E26: Amanamu's Tithe | I26: Combustível | J26: Só UM esqueleto: ele é o alvo do Pain Offering. Pode ser o Skeletal Warrior do Rattling Sceptre OU um Skeletal Arsonist — se você já usa o Arsonist, NÃO ative o Warrior também, porque os dois não cabem no Spirit do Ato 4. Sacrificial Lamb I garante que o Pain Offering espete esse esqueleto.
A27: Ato 4 | B27: Pain Offering | C27: — | D27: Prolonged Duration II | E27: Sacrificial Offering | I27: Buff de dano | J27: Continua sendo o botão de boss e não reserva Spirit. Com 1 esqueleto use Prolonged Duration II + Sacrificial Offering; Danse Macabre só quando tiver 2 esqueletos vivos.
A28: Ato 4 | B28: Withering Presence | C28: — | I28: Wither em área | J28: Inimigos na sua Presence recebem Wither (mais dano de chaos). Sozinha seria fraca, mas com Evergrasping Ring o zoo inteiro bate chaos extra.
A29: Ato 4 | B29: Sniper's Mark | C29: — | D29: Mark for Death | E29: Prolonged Duration II | I29: Marca o boss | J29: Mark for Death faz os hits no alvo marcado quebrarem Armour.
A30: Ato 4 | B30: Unearth | C30: — | D30: Prolonged Duration I | I30: Corpos + controle | J30: Bone Constructs duram mais.
A31: Ato 4 | B31: Tame Beast (2º beast: aura Haste) | C31: — | D31: Loyalty | E31: Last Gasp | I31: Aura bot | J31: O beast de aura vem logo depois do macaco: a aura de Haste acelera o zoo inteiro. Loyalty faz ele absorver parte do seu dano e Last Gasp mantém a aura ativa mesmo depois de morrer.
A32: Ato 4 | B32: Tame Beast (3º beast: só com Sylvan's Effigy) | C32: — | I32: Captura / guardar para o Effigy | J32: Com Trusted Kinship o limite é 2 companions de tipos diferentes (texto do keystone). O 3º só pode ficar ativo com o Sylvan's Effigy ("any number of Companions"). Até lá, use esta gem vazia só para capturar e guardar um Swarming Wisp / Plague Swarm com aura Physical.
A33: Ato 4 | B33: Raise Shield | C33: — | I33: Defesa ativa | J33: Só funciona com escudo ou buckler equipado. Com sceptre + maça (o set desta rota) ele não pode ser usado: deixe fora da barra se não tiver escudo.
A34: Ato 4 | B34: Skeletal Warrior (2º esqueleto) | C34: — | D34: Sacrificial Lamb I | I34: Só se sobrar Spirit | J34: Um 2º esqueleto libera o Danse Macabre no Pain Offering (+30% efeito). Com ~210 Spirit no nível 49 ele NÃO cabe junto com Silverfist + aura + Withering Presence + 1 esqueleto. Deixe para os Interlúdios.
A35: Interlúdios | B35: Tame Beast (Mighty Silverfist) | C35: — | D35: Feeding Frenzy II | E35: Rage II | F35: Rapid Attacks II | G35: Heft | H35: Muster | I35: CARRY | J35: Entra o 5º support: Muster. Com urso + macaco + aura bots + 5 tipos de esqueleto, são ~9 tipos → ~+63% more dano.
A36: Interlúdios | B36: Wild Protector | C36: Asc. | D36: Magnified Area I | E36: Armour Break III | F36: Minion Splash II | I36: Tank + área | J36: Minion Splash: o urso acerta o pack todo.
A37: Interlúdios | B37: Skeletal Warrior | C37: — | D37: Sacrificial Lamb II | E37: Amanamu's Tithe | I37: Combustível | J37: O esqueleto alvo do Pain Offering (Sacrificial Lamb II alcança 6 m). Se você usa Arsonist como esqueleto principal, ele ocupa esta vaga.
A38: Interlúdios | B38: Skeletal Frost Mage | C38: — | I38: Tipo extra (Muster) · opcional | J38: Cada TIPO diferente de minion dá +7% more dano ao macaco com Muster e o 2º esqueleto libera o Danse Macabre. Ative um por vez e só enquanto couber no Spirit: se o painel de skills mostrar Spirit negativo, desligue o último que entrou.
A39: Interlúdios | B39: Skeletal Arsonist | C39: — | I39: Tipo extra (Muster) · opcional | J39: Cada TIPO diferente de minion dá +7% more dano ao macaco com Muster e o 2º esqueleto libera o Danse Macabre. Ative um por vez e só enquanto couber no Spirit: se o painel de skills mostrar Spirit negativo, desligue o último que entrou.
A40: Interlúdios | B40: Skeletal Sniper | C40: — | I40: Tipo extra (Muster) · opcional | J40: Cada TIPO diferente de minion dá +7% more dano ao macaco com Muster e o 2º esqueleto libera o Danse Macabre. Ative um por vez e só enquanto couber no Spirit: se o painel de skills mostrar Spirit negativo, desligue o último que entrou.
...

Sheet Gear
A1: GEAR — do barato ao completo
A2: Barato = poucos Exalts no trade · Valor = bom custo-benefício · Completo = build como deve ser. Preços variam: use as faixas.
A3: Slot | B3: Barato | C3: Valor | D3: Completo | E3: Prioridade de affix | F3: Nota
A4: Main-hand | B4: Atos 1–2: spear rare (Twister). Ato 3: Rattling Sceptre (main) + Trenchtimbre. Início do Atlas: Chober Chaber Runeforged (~0,04 div). | C4: Chober Chaber Runeforged + Treefingers + The Vertex | D4: Chober Chaber Runeforged + Giant's Blood (Treefingers/keystone) + The Vertex | E4: Dano por golpe (min–max) > +Strength > qualquer coisa | F4: Catha's Balance: companions ganham 60% do dano da main-hand. 32% dos zoos com Effigy usam maça de 2 mãos + sceptre.
A5: Offhand | B5: Atos 1–2: qualquer offhand. Ato 3+: Rattling Sceptre (base rare, traz Skeletal Warrior) com +Minion Skills | C5: Sylvan's Effigy (~0,95 div) com Primate Idol + Rabbit Idol | D5: Sylvan's Effigy com Primate + Rabbit Idol | E5: Spirit > +Minion Skills > buffs de companion | F5: Com ~1 div o Effigy entra logo no início do Atlas.
A6: Capacete | B6: Vida + resists + Evasion | C6: +1/+2 Minion Skills com Idol of Ralakesh, ou Alpha's Howl (+100 Spirit) se faltar reserva | D6: +2 Minion Skills com Idol of Ralakesh, ou The Vertex para a Chober Chaber | E6: Minion Skills; vida; resist; Evasion→Deflection | F6: Starkonja's Head é defesa barata na campanha.
A7: Body Armour | B7: Evasion + vida + resists | C7: Forgotten Warden (~0,21 div) com Fox Idol | D7: Forgotten Warden Runemastered ou Morior Invictus (~6 div) | E7: Evasion; Deflection; vida; resist | F7: Forgotten Warden em 80% dos zoos: vida do zoo + Spirit Vessel grátis.
A8: Luvas | B8: Vida/resists/atributos | C8: Treefingers (Giant's Blood) se usar maça de 2 mãos | D8: Treefingers até ter Giant's Blood na árvore; depois rare de Evasion/Deflection com vida e resist | E8: Vida; resist; atributos | F8: Dano de player aqui é desperdício.
A9: Botas | B9: 10–20% MS (campanha), 25% no Ato 4 | C9: 30% MS + vida + resist | D9: 30% MS + Evasion/Deflection + resists | E9: Movement Speed SEMPRE primeiro | F9: Idol filler aqui já conta para a Idolatry.
A10: Amuleto | B10: Atributos / resists | C10: +Minion Skills + atributos | D10: +2/+3 Minion Skills + anoint Warlord Leader | E10: Minion Skills; atributos; resist
A11: Anéis | B11: Vida/resists/atributos | C11: Ventor's Gamble com resists positivas (+vida +Spirit) | D11: Kalandra's Touch copiando um rare perfeito | E11: Cap de resist; atributos | F11: Anéis são o lugar mais barato para fechar resist.
A12: Cinto | B12: Meginord's Girdle (Strength + frio) ou raro vida/resist | C12: Rare vida/resist ou Darkness Enthroned (Idols) | D12: Darkness Enthroned · Mageblood (luxo) | E12: Vida; resist; atributos | F12: Darkness Enthroned é CINTO (a planilha antiga dizia capacete).
A13: Jewels | B13: Emerald: Companion dano/vida; Sapphire: Minion +% Elemental Res | C13: From Nothing (~0,21 div) + Sapphires de minion crit | D13: From Nothing + Prism of Belief +2/+3 + Megalomaniac/Heart of the Well | E13: Minion crit/dano > attack speed > resist de minion | F13: Prism de roll ruim não vale só por ser unique.
A14: Charms | B14: Beira's Anguish · Sanguis Heroum · Arakaali's Gift (todos < 0,02 div) | C14: Nascent Hope · The Fall of the Axe | D14: Rite of Passage (luxo) | E14: Cobrir Burn / Poison / Bleed | F14: Com muita Evasion/Deflection, DoT é o que mata.
A15: Flasks | B15: Maior cura no menor tempo | C15: Lavianga's Spirits (mana constante) | D15: Lavianga's Spirits + life flask de recuperação instantânea | E15: Cura rápida
A17: ORDEM DE COMPRA — onde gastar primeiro
A18: # | B18: Item | C18: Fase | D18: Custo | E18: Impacto
A19: 1 | B19: Kit de leveling (Foxshade, Blackheart ×2, Goldrim, Wanderlust) | C19: Ato 1 | D19: Barato | E19: Campanha rápida
A20: 2 | B20: Rattling Sceptre + Trenchtimbre | C20: Ato 3 | D20: Barato | E20: Troca para minion
A21: 3 | B21: Chober Chaber + Treefingers | C21: Ato 3 | D21: Barato (~7 ex) | E21: O centro da build
A22: 4 | B22: The Vertex (versão Equipment) | C22: Ato 3 | D22: Valor (~0,4 div) | E22: Libera a Chober com sceptre
A23: 5 | B23: Enfolding Dawn (+100 Spirit) | C23: Ato 4 | D23: Barato | E23: Mais minions
A24: 6 | B24: Evergrasping Ring ×2 | C24: Ato 4 | D24: Barato | E24: Chaos para o zoo
A25: 7 | B25: Sylvan's Effigy + Primate/Rabbit Idol | C25: Nv 78 | D25: Valor (~1 div) | E25: Zoo ilimitado
A26: 8 | B26: Forgotten Warden + Lavianga's Spirits | C26: Nv 80 | D26: Valor (~0,3 div) | E26: Spirit Vessel + mana
A27: 9 | B27: Mageblood · Kalandra's Touch · Rite of Passage | C27: Endgame | D27: Luxo | E27: Teto

Sheet Spirit Planner
A1: SPIRIT PLANNER — cabe no seu Spirit?
A2: Amarelo = você edita. Estimativa: custo ÷ ((1 + increased) × more/less). Confira sempre o valor final no jogo.
A4: PARÂMETROS
A5: Spirit total | B5: =INÍCIO!B7 | C5: Vem do INÍCIO (B7).
A6: Trusted Kinship alocado? | B6: Sim | C6: 30% more eficiência p/ Companion · 20% less p/ o resto.
A7: Easy Going alocado? | B7: Sim | C7: +25% increased eficiência de Companion.
A8: Outros % increased eficiência (ex.: 0,10) | B8: 0 | C8: Jewels/itens. Digite como fração.
A9: Idolatry alocado? | B9: Não | C9: +2% eficiência por Idol.
A10: Nº de Idols equipados | B10: 0
A11: Increased (Companion) | B11: =IF(B7="Sim",0.25,0)+B8+IF(B9="Sim",0.02*B10,0)
A12: Increased (Outros) | B12: =B8+IF(B9="Sim",0.02*B10,0)
A13: Multiplicador more/less (Companion / Outro) | B13: =IF(B6="Sim",1.3,1) | C13: =IF(B6="Sim",0.8,1)
A15: SEU ZOO (exemplo preenchido: Ato 4 barato — troque pelos seus valores)
A16: Skill / Companion | B16: Ativo? | C16: Tipo | D16: Custo base | E16: Unidade | F16: Spirit usado | G16: Nota
A17: Mighty Silverfist | B17: Sim | C17: Companion | D17: 47.4 | E17: % | F17: =IF(B17<>"Sim",0,IF(E17="%",D17/100*$B$5,D17)/IF(C17="Companion",(1+$B$11)*$B$13,(1+$B$12)*$C$13)) | G17: 47,4% antes de reduções (guia)
A18: Quadrilla (2º beast) | B18: Sim | C18: Companion | D18: 42.3 | E18: % | F18: =IF(B18<>"Sim",0,IF(E18="%",D18/100*$B$5,D18)/IF(C18="Companion",(1+$B$11)*$B$13,(1+$B$12)*$C$13)) | G18: 42,3% antes de reduções (guia)
A19: Wild Protector | B19: Sim | C19: Companion | D19: 0 | E19: Flat | F19: =IF(B19<>"Sim",0,IF(E19="%",D19/100*$B$5,D19)/IF(C19="Companion",(1+$B$11)*$B$13,(1+$B$12)*$C$13)) | G19: Digite o custo mostrado no jogo
A20: Wind Dancer | B20: Sim | C20: Outro | D20: 0 | E20: Flat | F20: =IF(B20<>"Sim",0,IF(E20="%",D20/100*$B$5,D20)/IF(C20="Companion",(1+$B$11)*$B$13,(1+$B$12)*$C$13)) | G20: Digite o custo base do jogo
A21: Discipline / Malice | B21: Não | C21: Outro | D21: 0 | E21: Flat | F21: =IF(B21<>"Sim",0,IF(E21="%",D21/100*$B$5,D21)/IF(C21="Companion",(1+$B$11)*$B$13,(1+$B$12)*$C$13)) | G21: Digite o custo base do jogo
A22: Withering Presence | B22: Não | C22: Outro | D22: 0 | E22: Flat | F22: =IF(B22<>"Sim",0,IF(E22="%",D22/100*$B$5,D22)/IF(C22="Companion",(1+$B$11)*$B$13,(1+$B$12)*$C$13)) | G22: Sofre o 'less' do Trusted Kinship
A23: Skeletal Cleric | B23: Não | C23: Outro | D23: 0 | E23: Flat | F23: =IF(B23<>"Sim",0,IF(E23="%",D23/100*$B$5,D23)/IF(C23="Companion",(1+$B$11)*$B$13,(1+$B$12)*$C$13))
A24: Vile Vulture | B24: Não | C24: Companion | D24: 45.3 | E24: % | F24: =IF(B24<>"Sim",0,IF(E24="%",D24/100*$B$5,D24)/IF(C24="Companion",(1+$B$11)*$B$13,(1+$B$12)*$C$13)) | G24: T15
A25: Rhex | B25: Não | C25: Companion | D25: 31.2 | E25: % | F25: =IF(B25<>"Sim",0,IF(E25="%",D25/100*$B$5,D25)/IF(C25="Companion",(1+$B$11)*$B$13,(1+$B$12)*$C$13)) | G25: Aura barata
A26: Outro | B26: Não | C26: Outro | D26: 0 | E26: Flat | F26: =IF(B26<>"Sim",0,IF(E26="%",D26/100*$B$5,D26)/IF(C26="Companion",(1+$B$11)*$B$13,(1+$B$12)*$C$13))
A28: Spirit reservado | B28: =SUM(F17:F26)
A29: Spirit livre | B29: =B5-B28
A30: Uso | B30: =IFERROR(B28/B5,0)
A31: Status | B31: =IF(B29<0,"ESTOUROU — desligue algo",IF(B30>0.9,"No limite","OK"))
A33: Assunção: custos '%' são % do Spirit máximo antes de reduções (conforme o guia imortilize). Os valores 'Flat' você copia do jogo. É uma estimativa — o painel de skills do jogo é a verdade final.

Sheet Companions & Beasts
A1: COMPANIONS & BEASTS — o que capturar
A2: Custo = % de Spirit antes de reduções. Prioridade de aura: Extra Physical ou Haste Aura > Energy Shield ou Invulnerability Aura > Temporal Bubble > Elemental Resistance Aura
A3: Beast | B3: Onde | C3: Papel | D3: Custo base | E3: Tier | F3: Mods desejados | G3: Supports | H3: Requer
A4: Mighty Silverfist / Zekoa | B4: Ato 3 Jungle Ruins / mapas Riverside e Rupture | C4: Único DPS de verdade | D4: 0.474 | E4: S+ | F4: Extra Crits · Hasted · Extra Damage as Chaos/Physical | G4: Feeding Frenzy II · Rage III · Muster · Heft · Rapid Attacks II | H4: Tame Beast + The Natural Order
A5: Quill Crab (Porcupine) | B5: Ato 4 Whakapanu Island (essence e raros na praia) | C5: Aura bot barato | D5: 0.249 | E5: S | F5: Haste Aura (o mais fácil de achar) | G5: Loyalty · Last Gasp · Elemental Army · Meat Shield II · Minion Mastery | H5: Tame Beast
A6: Coconut Crab | B6: Ato 4 Whakapanu Island | C6: Aura bot barato | D6: 0.249 | E6: S | F6: Haste / Physical Aura | G6: Loyalty · Last Gasp · Elemental Army · Meat Shield II · Minion Mastery | H6: Tame Beast
A7: Swarming Wisp | B7: Ato 5 Ashen Forest (essence) | C7: Aura bot mais barato | D7: 0.21 | E7: S | F7: Qualquer aura T1 exceto Haste | G7: Loyalty · Last Gasp · Elemental Army · Meat Shield II · Minion Mastery | H7: Tame Beast
A8: Plague Swarm | B8: Ato 2 Mawdun Quarry (essence) | C8: Aura bot mais barato | D8: 0.21 | E8: A+ | F8: Aura T1 | G8: Loyalty · Last Gasp · Elemental Army · Meat Shield II · Minion Mastery | H8: Tame Beast
A9: Crag Leaper | B9: Ato 2 Vastiri Outskirts (essence) | C9: Aura bot | D9: 0.231 | E9: A+ | F9: Aura T1 (NUNCA Haste: é very_fast_movement) | G9: Loyalty · Last Gasp · Elemental Army · Meat Shield II · Minion Mastery | H9: Tame Beast
A10: Bramble Ape | B10: Ato 5 Kriar Village | C10: Aura bot | D10: 0.249 | E10: A | F10: Aura T1 | G10: Loyalty · Last Gasp · Elemental Army · Meat Shield II · Minion Mastery | H10: Tame Beast
A11: Rasp Scavenger | B11: Ato 5 Khari Crossing (essence) | C11: Aura bot reserva | D11: 0.267 | E11: A | F11: Aura T1 | G11: Loyalty · Last Gasp · Elemental Army · Meat Shield II · Minion Mastery | H11: Tame Beast
A12: Diretusk Boar | B12: Ato 3 Infested Barrens (garantido) | C12: Companion de campanha | D12: 0.39 | E12: A | F12: Qualquer | G12: Loyalty · Muster · Rapid Attacks II · Minion Mastery | H12: Tame Beast
A13: Antlion Charger | B13: Ato 3 Infested Barrens (garantido) | C13: Companion de campanha (setup de 3 do Mattjestic) | D13: 0.423 | E13: A | F13: Qualquer | G13: Loyalty · Last Gasp | H13: Tame Beast
A14: Azmerian Wolf | B14: Vem no Sylvan's Effigy | C14: 2º dano | D14: — | E14: S | F14: — | G14: Feeding Frenzy II · Rapid Attacks II · Rage III · Hulking Minions/Muster · Loyalty | H14: Sylvan's Effigy
A16: LOOP DE CAPTURA
A17: Passo 1 | B17: Ache um beast raro/unique capturável.
A18: Passo 2 | B18: Pause (atalho do Marketplace no botão do meio) e leia os mods antes de bater.
A19: Passo 3 | B19: Se não servir, siga em frente; se servir, use Tame Beast com ele em vida baixa.
A20: Passo 4 | B20: Compare a reserva no Spirit Planner: aura boa que estoura Spirit piora o setup.
A21: Passo 5 | B21: Suba a gem Tame Beast e coloque supports de sobrevivência (Meat Shield II, Loyalty).

Sheet Ascendência & Árvore
A1: ASCENDÊNCIA & ÁRVORE DE PASSIVAS
A2: Ordem obrigatória: Wild Protector → The Natural Order → The Catha's Balance → Idolatry. Texto dos nós conforme PoE2DB.
A3: # | B3: Nó | C3: Quando | D3: O que faz | E3: Por que
A4: 1 | B4: Wild Protector | C4: Ato 2 · Trial of the Sekhemas | D4: Invoca o Bear Spirit: salta nos inimigos com Maim, faz leech de vida no slam e dá Intimidate. Não conta no limite de companions. | E4: Tank grátis na campanha e base de Presence.
A5: 2 | B5: The Natural Order | C5: Ato 3 · Trial of Chaos | D5: Tame Beast pode capturar Unique Beasts (1 por vez). Unique tamed ganha 30% movement speed e é possuído por Azmeri Spirits aleatórios a cada 20s. | E5: Libera o Mighty Silverfist — nenhuma outra classe usa.
A6: 3 | B6: The Catha's Balance | C6: Atlas · Trial nível 60+ | D6: Companions causam dano de ataque adicional igual a 60% do dano da sua arma main-hand. | E6: Maior salto de dano da build. Arma de maior dano por golpe vence, independente de attack speed.
A7: 4 | B7: Idolatry | C7: Atlas · Trial nível 75+ | D7: +10% dano de companions e +2% reservation efficiency por Idol equipado; -4% em todas as resists por Augment que não é Idol. | E7: Escala dano e Spirit com Idols. Pegue só quando não depender de runas/soul cores para resist.
A9: PASSIVAS-CHAVE
B10: Nó | C10: Tipo | D10: O que faz | E10: Por que | F10: Quando
B11: Trusted Kinship | C11: Keystone | D11: 2 companions de tipos diferentes; 30% more eficiência de reserva de Companion; 20% less para as demais. | E11: Mesmo com o Effigy, os 30% more de eficiência continuam valendo. | F11: Ato 3 → sempre
B12: Giant's Blood | C12: Keystone | D12: Maças/machados/espadas de 2 mãos em uma mão; triplica requisitos de atributo das armas. | E12: Chober Chaber + sceptre ao mesmo tempo. | F12: Treefingers no Ato 3 → árvore no endgame
B13: Easy Going | C13: Notable | D13: 25% increased reservation efficiency de Companion. | E13: Mais companions no mesmo Spirit. | F13: Ato 4
B14: Polymathy | C14: Notable | D14: Atributos. | E14: Ajuda com os requisitos triplicados. | F14: Giant's Blood
B15: Mind Over Matter | C15: Keystone | D15: Todo dano sai da mana antes da vida; 50% less recuperação de mana. | E15: Com +100 mana da Chober e Lavianga's Spirits vira uma camada de defesa enorme. | F15: Endgame (nv 90+)
A17: ÁRVORE POR ETAPA
A18: Nível | B18: Foco | C18: Dano | D18: Defesa | E18: Spirit | F18: Não faça
A19: 1–30 | B19: Twister/projétil | C19: Twister | D19: Vida + Evasion | E19: — | F19: Minion cedo demais
A20: 31–45 | B20: Trusted Kinship + Bonds (Mamba, Cat) + Unspoken Bond | C20: Macaco | D20: Blur, Catlike Agility, Escape Velocity | E20: Trusted Kinship | F20: Nós de ataque
A21: 46–64 | B21: Easy Going, Inspiring Ally, Bond of the Wolf/Owl | C21: Macaco + Muster | D21: Evasion | E21: Easy Going | F21: Sacrificar resists
A22: 65–77 | B22: Sturdy Ally, Captivating Companionship, Sic 'Em, Howling Primate | C22: Catha + Chober | D22: Enhanced Reflexes | E22: Mais companions | F22: Julgar arma por DPS
A23: 78–89 | B23: Giant's Blood, Polymathy, Deflection, Long Distance Relationship | C23: Zekoa + Azmerian Wolf | D23: Enduring/Avoiding Deflection | E23: Effigy | F23: Tirar Trusted Kinship
A24: 90+ | B24: Mind Over Matter, The Soul Meridian, Beastial Skin | C24: Zoo inteiro | D24: MoM | E24: Idolatry | F24: MoM sem mana
A26: Dica: use o planner da Mobalytics (links em Fontes) para ver o caminho exato de cada ato — as cores Amarelo/Rosa/Verde são árvore principal / Weapon Set 1 / Weapon Set 2.

Sheet Quests
A1: RECOMPENSAS PERMANENTES — não pule
A2: +130 Spirit, resistências e weapon set points ao longo da campanha. Marque Feito.
A3: Ato | B3: Área | C3: Boss / Quest | D3: Recompensa | E3: Prioridade | F3: Status
A4: Ato 1 | B4: Clearfell | C4: Beira of the Rotten Pack | D4: +10% resistência a frio | E4: Alta | F4: Pendente
A5: Ato 1 | B5: Hunting Grounds | C5: The Crowbell | D5: 2 Weapon Set Passive Points | E5: Alta | F5: Pendente
A6: Ato 1 | B6: Freythorn | C6: The King in the Mists | D6: +30 Spirit | E6: CRÍTICA | F6: Pendente
A7: Ato 1 | B7: Ogham Farmlands | C7: Una's Hut | D7: 2 Weapon Set Passive Points | E7: Alta | F7: Pendente
A8: Ato 1 | B8: Ogham Manor | C8: Candlemass, the Living Rite | D8: +20 vida máxima | E8: Alta | F8: Pendente
A9: Ato 2 | B9: Keth | C9: Kabala, Constrictor Queen | D9: 2 Weapon Set Passive Points | E9: Alta | F9: Pendente
A10: Ato 2 | B10: Valley of the Titans | C10: Medallion | D10: +1 Charm Slot e 30% charm charges | E10: Alta | F10: Pendente
A11: Ato 2 | B11: Deshar | C11: Final Letter | D11: 2 Weapon Set Passive Points | E11: Alta | F11: Pendente
A12: Ato 2 | B12: Spires of Deshar | C12: Sisters of Garukhan | D12: +10% resistência a raio | E12: Alta | F12: Pendente
A13: Ato 3 | B13: Jungle Ruins | C13: Mighty Silverfist | D13: 2 Weapon Set Points + alvo do Tame | E13: CRÍTICA | F13: Pendente
A14: Ato 3 | B14: Venom Crypts | C14: Venom Draught | D14: 25% Stun Threshold | E14: Média | F14: Pendente
... A32: Interlúdio | B32: Howling Caves | C32: The Abominable Yeti | D32: 2 Weapon Set Passive Points | E32: Alta | F32: Pendente

Sheet Tricks Pro
A1: TRICKS DE PROFISSIONAL
A2: O que streamers e jogadores de topo fazem para ganhar tempo, dano e segurança.
A3: Categoria | B3: Nível | C3: Trick | D3: Como fazer
A4: Captura | B4: Fácil | C4: Limite de companions | D4: Base: 1 companion. Trusted Kinship (keystone) ou Yriel's Fostering (body): 2 companions de TIPOS diferentes — não somam entre si. Sylvan's Effigy: qualquer número de tipos diferentes. O urso do Wild Protector não conta no limite.
A5: Captura | B5: Médio | C5: Rota de aura bots do Mattjestic | D5: Antes do Sylvan's Effigy só cabe 1 beast de aura (limite de 2 companions com Trusted Kinship). 1) Ato 4 Whakapanu Island: essence de crabs na praia (Quill/Coconut Crab ~25%) até achar Haste Aura. 2) Ato 5 Ashen Forest: Swarming Wisp (21%) com qualquer aura T1 exceto Haste. 3) Ato 2 Vastiri Outskirts: Crag Leaper (23,1%). Guarde auras T1 diferentes e substitua crabs duplicados. Os beasts extras entram quando você equipar o Effigy.
A6: Captura | B6: Fácil | C6: Haste não aparece em beasts muito rápidos | D6: Beasts com a tag very_fast_movement (ex.: Crag Leaper) nunca rolam Haste Aura. Procure Haste em crabs.
A7: Dano | B7: Médio | C7: Conte os tipos de minion para o Muster | D7: Urso, macaco, cada beast diferente, Azmerian Wolf, Wolf Pack, Spirit Vessel e cada tipo de esqueleto contam como um tipo. Cada um soma 7% more dano nos companions com Muster.
A8: Spirit | B8: Fácil | C8: Rattling Sceptre já traz o esqueleto | D8: O Rattling Sceptre é uma base comum (não unique) que já traz a gem Skeletal Warrior. Um único esqueleto basta como alvo do Pain Offering até o Effigy; o segundo só quando sobrar Spirit.
A9: Economia | B9: Fácil | C9: The Vertex: confira a versão | D9: Só a versão com 'Equipment has no Attribute Requirements' libera a Chober Chaber com Giant's Blood. Filtre por esse mod no trade.
A10: Dano | B10: Médio | C10: Pain Offering sem cair no boss | D10: Brutus' Brain no Pain Offering deixa o espinho imune a dano, então o buff não some quando o boss acerta a área. Danse Macabre precisa de 2 esqueletos vivos: só coloque quando o Spirit permitir o 2º esqueleto (Interlúdios). Depois do Effigy, o Skeletal Cleric com Sacrificial Lamb II vira o alvo.
A11: Captura | B11: Fácil | C11: Como o Tame Beast funciona | D11: Use o Tame Beast num raro: ele fica envolto em wisps (Hinder) por ~8–12s. Mate enquanto os wisps estão nele para capturar. O beast guarda até 4 mods de monstro, então capture o que tem os mods que você quer.
A12: Silverfist | B12: Médio | C12: Zekoa com 3+ mods | D12: Riverside ou Rupture + 1 Cruel Hegemony + 2 tablets raros com 'Unique Monsters have 1 additional Rare Modifier'. Ordem de mods: Extra Crits > Hasted > Extra Damage as Chaos/Physical > Soul Eater.
A13: Silverfist | B13: Avançado | C13: Reroll de mods morrendo (softcore) | D13: Com Doryani como Atlas Master e o nó Stitch the Flesh (revive extra), dá para morrer de propósito na luta e o boss volta com mods novos. Rituals perto de City biomes geram vários Zekoas no mesmo map.
A14: Dano | B14: Médio | C14: Giant's Blood + The Vertex | D14: Treefingers dá Giant's Blood (maça 2 mãos + sceptre), mas triplica requisitos. The Vertex remove requisitos de gems (e, em algumas versões, do equipamento). Soul Core of Cholotl converte 40% para Dex.
... A39: Economia | B39: Fácil | C39: Compre a Chober Chaber cedo | D39: A Chober Chaber costuma custar poucos Exalts. Compre já Runeforged no Ato 3–4 e guarde: com a Catha's Balance ela vira a principal fonte de dano do zoo.

Sheet Diagnóstico
A1: DIAGNÓSTICO — o dano caiu? algo deu errado?
A2: Sintoma → causa provável → correção. Abaixo, análise do seu setup atual (imagens da planilha antiga).
A3: Sintoma | B3: O que fazer
A4: O zoo parou de bater / sumiu | B4: Spirit acima do limite desliga skills. Veja a reserva no painel de skills e desligue uma não-companion.
A5: Dano caiu depois de trocar arma | B5: A Catha's Balance usa a main-hand do set ativo. Volte para o set com a arma forte.
A6: Silverfist fraco no Ato 4 | B6: Confira os supports do macaco: Feeding Frenzy II · Rage II · Rapid Attacks II · Heft (Muster só entra nos Interlúdios, quando tiver vários tipos de minion). Suba o nível da gem Tame Beast e use Sniper's Mark no boss.
A7: Resists caíram do nada | B7: Idolatry: -4% por Augment que não é Idol. Troque runas/soul cores por Idols ou recapar via gear.
A8: Morro para bleed/burn/poison | B8: Charms Staunching / Ruby / Antidote e resist de chaos. Evasion não protege contra DoT.
A9: Bosses demoram | B9: Sniper's Mark no boss, Armour Break III no macaco, e confira se os companions estão na sua Presence.
A10: Tirei Trusted Kinship com o Effigy e o Spirit estourou | B10: Recoloque o keystone: os 30% more de reservation efficiency continuam valendo mesmo com companions ilimitados.
A11: Não consigo equipar a Chober Chaber com Giant's Blood | B11: Os requisitos triplicam. Use The Vertex, Soul Core of Cholotl (40% vira Dex) ou atributos na árvore.
A12: Zekoa com poucos mods | B12: Use tablets com 'Unique Monsters have 1 additional Rare Modifier' + Cruel Hegemony em Riverside/Rupture.
A13: Pain Offering não dá buff | B13: Ele precisa de um esqueleto vivo por perto (Warrior, Arsonist, Sniper ou Cleric) com Sacrificial Lamb. Danse Macabre precisa de 2 esqueletos: com 1 só, troque por Sacrificial Offering.
A14: Mana acaba no endgame | B14: Lavianga's Spirits (flask constante) + a mana da Chober Chaber; com Mind Over Matter a mana também é sua defesa.
A15: Não cabe tudo no Spirit | B15: Ative na ordem da aba Skills: macaco → beast de aura → Withering Presence → 1 esqueleto. Curses, marks, Pain Offering e Unearth não reservam Spirit. Se o painel mostrar Spirit negativo, desligue o último minion que entrou.
A17: SEU SETUP ATUAL — análise
A18: Silverfist — Feeding Frenzy II, Rage II, Rapid Attacks II, Heft, Muster | B18: Certo: é exatamente o setup do Mattjestic (Act 5 / mapping). Com Rage III no lugar do Rage II a partir do mapping.
A19: Wild Protector — Magnified Area I, Armour Break III, Minion Splash II | B19: Certo para Ato 4 → mapping T1-10 (o Mattjestic usa os mesmos três e adiciona Minion Mastery). No endgame vira Romira's Requital + Catha's Brilliance.
A20: Pain Offering — Danse Macabre, Prolonged Duration II | B20: Central na rota. Danse Macabre só funciona com 2 esqueletos vivos; com 1 esqueleto (Ato 3–4) use Sacrificial Offering no lugar. Brutus' Brain entra no endgame (o espinho não morre).
A21: Skeletal Sniper + Withering Presence | B21: Os dois fazem sentido: o Sniper conta como mais um tipo de minion para o Muster e serve de alvo do Pain Offering; o Withering Presence vale com 2× Evergrasping Ring (dano de chaos nos aliados). Sem os anéis, troque o Withering Presence.

Sheet Atlas
A1: ATLAS — checklist e árvore
A2: Da entrada no T1 até Uber Arbiter. Nós do Atlas conforme o guia T15+ (0.5.5).
A3: Etapa | B3: Meta | C3: Upgrade-chave
A4: Antes do T1 | B4: 75% resists · 25–30% MS · Silverfist com sockets | C4: Catha's Balance se já tiver
A5: T1–T5 | B5: Zero mortes aleatórias · +Minion ranks | C5: Sceptre raro com Spirit
A6: T6–T10 | B6: Bosses rápidos · main-hand de alto dano | C6: Deflection começando
A7: T11–T15 | B7: Zoo estável · charms de DoT | C7: Chober Chaber + Rattling Sceptre (ou Sylvan's Effigy)
A8: T15+ Value | B8: Lazy clear · Azmerian Wolf / Wolf Pack | C8: Sylvan's Effigy + Idolatry
A9: Arbiter / Uber | B9: Mana Remnants · aura beasts · 350 Spirit | C9: From Nothing / Prism of Belief
A11: ÁRVORE DO ATLAS
A12: Grupo | B12: Nó
A13: Standard | B13: Unseen Rivers: Vivid
A14: Standard | B14: Craftsman's Creed: Skill of Hand
A15: Standard | B15: Well-equipped Opponents: Dexterity
A16: Standard | B16: Blood on the Stones: Bosses
A17: Standard | B17: Divined Blessing: Seeking Shrine
A18: Standard | B18: The Chosen Path: Azmeri Spirits
A19: Standard | B19: Sacred Sap: Commingled
A20: Standard | B20: Overlord's Influence: Azmeri Spirit
A21: Standard | B21: Overlord's Domain: Essence
A22: Standard | B22: The Journey Ahead: Effectiveness
A23: Standard | B23: Avatar of Evolution
... A46: Vaal Temple | B46: Atziri's Assets: Designs

Sheet Otimizações & Meta
A1: NOSSA ROTA OTIMIZADA — o que mudou e por quê
A2: Baseado em 5649 Spirit Walkers com Sylvan's Effigy + 24 zoos nível 98–99 da liga Forbidden Rites (poe.ninja, 15/09/2026).
A3: # | B3: Otimização | C3: Evidência (dados) | D3: Por quê | E3: Guia base dizia
A4: 1 | B4: Por que a Chober Chaber é o centro | C4: Mattjestic usa do 'Giant's Blood' ao 100m DPS; 24% dos zoos com Effigy no poe.ninja. | D4: A Catha's Balance dá aos companions 60% do dano da sua main-hand por golpe. A Chober é uma maça de 2 mãos com dano base enorme e ainda dá +2 a +4 Minion Skills, +50 Spirit e +100 mana. Nenhuma outra arma entrega tudo isso junto. | E4: Rotas antigas: Tyranny's Grip / spear rare.
A5: 2 | B5: Giant's Blood: 2 mãos + sceptre | C5: Keystone em todas as variantes endgame do Mattjestic; 34% dos zoos com Effigy. | D5: Sem Giant's Blood, a Chober ocuparia as duas mãos e você perderia o sceptre (Skeletal Warrior no começo, Sylvan's Effigy depois). Treefingers dá o keystone cedo; no endgame ele vai para a árvore.
A6: 3 | B6: The Vertex resolve os requisitos triplicados | C6: Variante 0.5.5 Mapping: 'The Vertex (equipment)'. | D6: Giant's Blood triplica os requisitos de atributo das armas marciais. A versão do The Vertex com 'Equipment has no Attribute Requirements' zera isso e libera a Chober já no Ato 3.
A7: 4 | B7: Pain Offering é central (não opcional) | C7: Presente em quase todas as variantes do Ato 3 ao 21m DPS. | D7: Espeta um esqueleto e dá aos minions próximos até +29% attack speed e +58% dano (mais 30% com Danse Macabre e 30% com Sacrificial Offering). Brutus' Brain impede o espinho de morrer. | E7: Eu tinha chamado de 'botão opcional' — estava errado.
A8: 5 | B8: Esqueletos existem para o Muster e para o Pain Offering | C8: Mattjestic (Ato 5) usa Warrior, Arsonist, Sniper, Frost Mage e Reaver sem supports de dano — mas só com Spirit sobrando. Entre um por vez. | D8: Muster: +7% more dano para CADA tipo diferente de minion que revive. Cada tipo de esqueleto que couber no Spirit soma +7% no macaco e ainda serve de alvo do Pain Offering. 1 de cada tipo basta.
A9: 6 | B9: Skeletal Cleric é alvo válido do Pain Offering | C9: Endgame: Cleric com Sacrificial Lamb II + Tecrod's Revenge. | D9: O Cleric é um esqueleto. Quando o Effigy tira o Rattling Sceptre, o Cleric (com Sacrificial Lamb II) vira o esqueleto espetado e ainda cura/revive. | E9: Eu tinha dito que o Cleric não servia — estava errado.
A10: 7 | B10: Withering Presence + Evergrasping Ring | C10: Ato 4–5 do Mattjestic: 2× Evergrasping Ring + Withering Presence. | D10: O anel faz os aliados ganharem 15–25% do dano como chaos extra; o Wither faz os inimigos receberem mais chaos. Juntos se multiplicam. Sem o anel, o Wither é fraco. | E10: Eu tinha mandado tirar o Withering Presence — só vale tirar se não usar o anel.
A11: 8 | B11: Sem Ball Lightning / Lightning Warp | C11: Nenhuma das 26 variantes usa. | D11: Eram mobilidade do jogador e não ajudam o macaco. O espaço vai para curse, marks, Pain Offering e Refutation. | E11: O guia antigo usava.
A12: 9 | B12: Mace Strike + Einhar's Beastrite não é dano | C12: Variantes endgame (13–24). | D12: O Mace Strike vem da própria Chober. Com Einhar's Beastrite ele só finaliza inimigos com vida baixa, e cada raro finalizado te dá 2 modificadores dele por 300 s (Haste, Extra Damage…).
A13: 10 | B13: Refutation + itens Runeforged | C13: Do mapping T1–10 ao endgame. | D13: Refutation gasta todo o seu Runic Ward para bloquear todos os hits por um tempo. Runic Ward vem de armaduras Runeforged/Runemastered — é por isso que as armaduras do Mattjestic são Runeforged.
A14: 11 | B14: Aura bots baratos em Spirit | C14: Tier-list do Mattjestic (0.5). | D14: Com Sylvan's Effigy, o objetivo são 2–3 auras T1 (antes dele só cabe 1) (Physical/Haste > ES/Invulnerability > Temporal Bubble > Elemental Res) em beasts de 21–25% de Spirit: Swarming Wisp, Crag Leaper, Quill/Coconut Crab. | E14: Beasts de 40%+ de Spirit.
A16: BODY ARMOUR (% de uso)
B17: Forgotten Warden | C17: 0.8
B18: Morior Invictus | C18: 0.11
B19: Rare | C19: 0.06
A21: MAIN-HAND (% de uso)
B22: Tyranny's Grip | C22: 0.39
B23: Trenchtimbre | C23: 0.26
B24: Chober Chaber | C24: 0.24
B25: The Hammer of Faith | C25: 0.06
A27: CONFIGURAÇÃO DE ARMAS (% de uso)
B28: Arma 1 mão / Sceptre | C28: 0.62
B29: Maça 2 mãos / Sceptre (Giant's Blood) | C29: 0.32
B30: Spear / Sceptre | C30: 0.02
A32: KEYSTONES (% de uso)
B33: Trusted Kinship | C33: 0.99
B34: Giant's Blood | C34: 0.34
B35: Mind Over Matter | C35: 0.27
B36: Iron Reflexes | C36: 0.04
B37: Chaos Inoculation | C37: 0.02
A39: ASCENDÊNCIA (% de uso)
B40: The Natural Order | C40: 1
B41: Wild Protector | C41: 0.99
B42: The Catha's Balance | C42: 0.97
B43: Idolatry | C43: 0.86
A45: COMPANIONS (SKILLS PRINCIPAIS) (% de uso)
B46: Wild Protector | C46: 0.99
...

Sheet Uniques
A1: UNIQUES DA BUILD — preço real, uso no meta e quando entram
A2: Preços em Divine Orb (1 div ≈ 353 Exalted) no poe.ninja em 15/09/2026. 'Uso' = % dos zoos com Sylvan's Effigy. Filtre por Fase/Faixa.
B3: Unique | C3: Slot | D3: Faixa | E3: Preço (div) | F3: Uso | G3: Fase | H3: Por quê | I3: Mods principais | J3: Como / versões
B4: Splinter of Lorrata | C4: Main-hand | D4: Barato | E4: 0.003 | F4: — | G4: Ato 1 | H4: Leveling nível 1: sempre envenena. Troque pelo Skysliver no 16. | I4: Adds (2-3) to (6-8) Physical Damage Deal no Elemental Damage 20% increased Melee Strike Range with this weapon Any number of Poisons from this Weapon can affect a target at the same time Always Poison on Hit with this weapon
B5: Foxshade | C5: Body Armour | D5: Barato | E5: 0.006 | F5: — | G5: Ato 1 | H5: Leveling: +Evasion, +Dexterity e Movement Speed com vida cheia. | I5: +(50-70) to Evasion Rating +(20-30) to Dexterity 10% increased Movement Speed when on Full Life 100% increased Evasion Rating when on Full Life
B6: Surefooted Sigil | C6: Amuleto | D6: Barato | E6: 0.006 | F6: — | G6: Ato 1 | H6: Leveling: vida, Dexterity e dodge roll maior. | I6: +(40-60) to maximum Life +(5-15) to Dexterity +1 metre to Dodge Roll distance 50% increased Evasion Rating if you've Dodge Rolled Recently
B7: Blackheart | C7: Anel | D7: Barato | E7: 0.009 | F7: — | G7: Ato 1 | H7: Leveling: dano de chaos nos ataques, regen de vida e Intimidate. Use dois. | I7: (3-6) Life Regeneration per second Adds (4-6) to (8-10) Chaos Damage to Attacks +(10-20)% of Armour also applies to Chaos Damage 25% chance to Intimidate Enemies for 4 seconds on Hit
B8: Wanderlust | C8: Botas | D8: Barato | E8: 0.014 | F8: — | G8: Ato 1 | H8: Leveling: 20% Movement Speed e imune a Slow. | I8: 20% increased Movement Speed +(10-20) to maximum Energy Shield +5 to Dexterity Your speed is unaffected by Slows
B9: Goldrim | C9: Capacete | D9: Barato | E9: 0.028 | F9: — | G9: Ato 1 | H9: Leveling: +25–35% todas as resistências. | I9: +(30-50) to Evasion Rating 10% increased Rarity of Items found +(25-33)% to all Elemental Resistances
B10: Meginord's Girdle | C10: Cinto | D10: Barato | E10: 0.009 | F10: — | G10: Ato 2 | H10: +40–50 Strength e resist a frio: resolve requisitos de supports na campanha. | I10: +(40-50) to Strength +(10-15)% to Cold Resistance 50% increased Flask Charges used 100% increased Flask Charges gained | J10: ≈ 0,009 div
B11: Skysliver | C11: Main-hand | D11: Valor | E11: 0.106 | F11: — | G11: Ato 2 | H11: Leveling: spear de raio com attack speed para o Twister no Ato 2. | I11: No Physical Damage Adds 1 to (80-120) Lightning Damage (15-30)% increased Attack Speed (50-100)% increased chance to Shock Rolls only the minimum or maximum Damage value for each Damage Type
B12: Midnight Braid | C12: Cinto | D12: Barato | E12: 0.003 | F12: — | G12: Ato 3 | H12: 50% do dano recebido é recuperado como mana, +resistências e +mana: sustenta Pain Offering, Unearth e marks. | I12: +(30-50) to maximum Mana +(5-10)% to all Elemental Resistances 50% of Damage taken Recouped as Mana
